<mujoco model="xarm7">
    <compiler angle="radian" meshdir="mesh" />
    <size njmax="500" nconmax="100" />
<!--    <include file="../../../../adept_models/scenes/basic_scene.xml"/>-->
    <include file="../kitchen/assets/oven_asset.xml"/>
    <include file="../kitchen/assets/counters_asset.xml"/>
<!--    <include file="../../kitchen/assets/backwall_asset.xml"/>-->
<!--    <include file="../../kitchen/assets/slidecabinet_asset.xml"/>-->
<!--    <include file="../../kitchen/assets/hingecabinet_asset.xml"/>-->
<!--    <include file="../../kitchen/assets/microwave_asset.xml"/>-->
<!--    <include file="../../kitchen/assets/kettle_asset.xml"/>-->


    <asset>
        <mesh name="link_base" file="link_base.STL" />
        <mesh name="link1" file="link1.STL" />
        <mesh name="link2" file="link2.STL" />
        <mesh name="link3" file="link3.STL" />
        <mesh name="link4" file="link4.STL" />
        <mesh name="link5" file="link5.STL" />
        <mesh name="link6" file="link6.STL" />
        <mesh name="link7" file="link7.STL" />
        <texture builtin="flat" height="32" name="table_tex" rgb1="0.5 0.86 0.60" type="cube" width="32"/>
        <texture builtin="flat" height="32" name="peg_tex" rgb1="0.2 0.6 0.99" type="2d" width="32"/>
        <material name="table_mat" shininess="0.01" specular="0.75" texture="table_tex"/>
        <material name="peg_mat" shininess="0.01" specular="0.75" texture="peg_tex"/>
    </asset>
    <worldbody>
        <geom type="mesh" rgba="1 1 1 1" mesh="link_base" />
        <body name="link1" pos="0 0 0.267">
            <inertial pos="-0.0042142 0.02821 -0.0087788" quat="0.917781 -0.277115 0.0606681 0.277858" mass="0.42603" diaginertia="0.00144551 0.00137757 0.000823511" />
            <joint name="joint1" pos="0 0 0" axis="0 0 1" limited="true" range="-6.28319 6.28319" damping="10" frictionloss="1" />
            <geom type="mesh" rgba="1 1 1 1" mesh="link1" />
            <body name="link2" pos="0 0 0" quat="0.707105 -0.707108 0 0">
                <inertial pos="-3.3178e-05 -0.12849 0.026337" quat="0.447793 0.894132 -0.00224061 0.00218314" mass="0.56095" diaginertia="0.00319151 0.00311598 0.000980804" />
                <joint name="joint2" pos="0 0 0" axis="0 0 1" limited="true" range="-2.059 2.0944" damping="10" frictionloss="1" />
                <geom type="mesh" rgba="1 1 1 1" mesh="link2" />
                <body name="link3" pos="0 -0.293 0" quat="0.707105 0.707108 0 0">
                    <inertial pos="0.04223 -0.023258 -0.0096674" quat="0.883205 0.339803 0.323238 0.000542237" mass="0.44463" diaginertia="0.00133227 0.00119126 0.000780475" />
                    <joint name="joint3" pos="0 0 0" axis="0 0 1" limited="true" range="-6.28319 6.28319" damping="5" frictionloss="1" />
                    <geom type="mesh" rgba="1 1 1 1" mesh="link3" />
                    <body name="link4" pos="0.0525 0 0" quat="0.707105 0.707108 0 0">
                        <inertial pos="0.067148 -0.10732 0.024479" quat="0.0654142 0.483317 -0.738663 0.465298" mass="0.52387" diaginertia="0.00288984 0.00282705 0.000894409" />
                        <joint name="joint4" pos="0 0 0" axis="0 0 1" limited="true" range="-0.19198 3.927" damping="5" frictionloss="1" />
                        <geom type="mesh" rgba="1 1 1 1" mesh="link4" />
                        <body name="link5" pos="0.0775 -0.3425 0" quat="0.707105 0.707108 0 0">
                            <inertial pos="-0.00023397 0.036705 -0.080064" quat="0.981064 -0.19003 0.00637998 0.0369004" mass="0.18554" diaginertia="0.00099553 0.000988613 0.000247126" />
                            <joint name="joint5" pos="0 0 0" axis="0 0 1" limited="true" range="-6.28319 6.28319" damping="5" frictionloss="1" />
                            <geom type="mesh" rgba="1 1 1 1" mesh="link5" />
                            <body name="link6" pos="0 0 0" quat="0.707105 0.707108 0 0">
                                <inertial pos="0.058911 0.028469 0.0068428" quat="-0.188705 0.793535 0.166088 0.554173" mass="0.31344" diaginertia="0.000827892 0.000768871 0.000386708" />
                                <joint name="joint6" pos="0 0 0" axis="0 0 1" limited="true" range="-1.69297 3.14159" damping="2" frictionloss="1" />
                                <geom type="mesh" rgba="1 1 1 1" mesh="link6" />
                                <site name="grip_base" pos="0 0 0" rgba="10 0 0 1" size="0.01 0.01 0.01"/>
                                <body name="link7" pos="0.076 0.097 0" quat="0.707105 -0.707108 0 0">
                                    <inertial pos="-1.5846e-05 -0.0046377 -0.012705" quat="0.495801 0.504435 -0.503065 0.496642" mass="0.31468" diaginertia="0.000260352 0.00016985 0.000119208" />
                                    <joint name="joint7" pos="0 0 0" axis="0 0 1" limited="true" range="-6.28319 6.28319" damping="2" frictionloss="1" />
                                    <geom type="mesh" rgba="0.753 0.753 0.753 1" mesh="link7" />
                                </body>
                            </body>
                        </body>
                    </body>
                </body>
            </body>
        </body>

        <body name='desk' pos='-0.1 0.75 0'>

            <body name="counters1" pos="0 0 0" >
                <include file="../kitchen/assets/counters_chain.xml"/>
            </body>
            <body name="oven" pos="0 0 0" >
                <include file="../kitchen/assets/oven_chain.xml"/>
<!--            </body>-->
<!--            <body name="backwall" pos="0 0 0" >-->
<!--                <include file="../kitchen/assets/backwall_chain.xml"/>-->
<!--            </body>-->
<!--            <body name="slidecabinet" pos="0.4 0.3 2.6" >-->
<!--                <include file="../kitchen/assets/slidecabinet_chain.xml"/>-->
<!--            </body>-->
<!--            <body name="hingecabinet" pos="-0.504 0.28 2.6" >-->
<!--                <include file="../kitchen/assets/hingecabinet_chain.xml"/>-->
<!--            </body>-->
<!--            <body name="microwave" pos="-0.750 -0.025 1.6" euler="0 0 0.3">-->
<!--                <include file="../kitchen/assets/microwave_chain.xml"/>-->
<!--            </body>-->
        </body>
<!--        <body name="kettle" pos="-0.269 0.35 1.626">-->
<!--            <freejoint/>-->
<!--            <include file="../kitchen/assets/kettle_chain.xml"/>-->
<!--        </body>-->

<!--        <body name="table" pos="0.6 0 -0.1">-->
<!--            <geom name="table_base" pos="0 0 -0.1" rgba="0.94 0.70 0.49 1" size="0.4 0.4 0.15" type="box"/>-->
<!--            <geom material="table_mat" name="table_back_side" pos="-0.21 0 0.1" rgba="0.94 0.70 0.49 1"-->
<!--                  size="0.19 0.4 0.05" type="box"/>-->
<!--            <geom material="table_mat" name="table_front_side" pos="0.21 0 0.1" rgba="0.94 0.70 0.49 1"-->
<!--                  size="0.19 0.4 0.05" type="box"/>-->
<!--            <geom material="table_mat" name="table_left_side" pos="0. 0.21 0.1" rgba="0.74 0.50 0.79 1"-->
<!--                  size="0.02 0.19 0.05" type="box"/>-->
<!--            <geom material="table_mat" name="table_right_side" pos="0. -0.21 0.1" rgba="0.74 0.50 0.49 1"-->
<!--                  size="0.02 0.19 0.05" type="box"/>-->
<!--            <site name="target" pos="0 0. 0.1" rgba="1 1 1 1" size="0.02 0.01 0.01"/>-->
<!--        </body>-->

        <body name="skill" pos="0.5 0.0 0.5">
            <geom conaffinity="0" contype="0" name="skill" pos="0 0 0" rgba="0.7 0.2 0.2 0.5" size=".015" type="sphere"/>
            <geom conaffinity="0" contype="0" name="x" pos="0 0 0.08" size="0.012 0.08" type="cylinder" rgba="0.7 0.2 0.2 0.5"/>
        </body>

    </worldbody>
    <actuator>
        <position ctrllimited="true" ctrlrange="-3.14 3.14" joint="joint1" kp="30" name="pos_j1" forcelimited="true" forcerange="-200 200"/>
        <position ctrllimited="true" ctrlrange="-2.06 2.09" joint="joint2" kp="20" name="pos_j2" forcelimited="true" forcerange="-100 100"/>
        <position ctrllimited="true" ctrlrange="-3.14 3.14" joint="joint3" kp="15" name="pos_j3" forcelimited="true" forcerange="-100 100"/>
        <position ctrllimited="true" ctrlrange="-0.19 3.92" joint="joint4" kp="10" name="pos_j4" forcelimited="true" forcerange="-30 30"/>
        <position ctrllimited="true" ctrlrange="-3.14 3.14" joint="joint5" kp="5" name="pos_j5" forcelimited="true" forcerange="-30 30"/>
        <position ctrllimited="true" ctrlrange="-1.69 3.14" joint="joint6" kp="2" name="pos_j6" forcelimited="true" forcerange="-30 30"/> -->
        <position ctrllimited="true" ctrlrange="-3.14 3.14" joint="joint7" kp="5" name="pos_j7" forcelimited="true" forcerange="-30 30"/>
    </actuator>
</mujoco>
